{
 "cells": [
  {
   "cell_type": "code",
   "execution_count": 1,
   "id": "03a30294-fbc7-450e-bf4d-b7a85950086b",
   "metadata": {},
   "outputs": [],
   "source": [
    "import pyshark\n",
    "from pyshark_functions import get_packets"
   ]
  },
  {
   "cell_type": "code",
   "execution_count": 2,
   "id": "bf68228d-ed2a-4d66-b99b-121e9af222ad",
   "metadata": {},
   "outputs": [
    {
     "name": "stderr",
     "output_type": "stream",
     "text": [
      "C:\\ProgramData\\anaconda3\\lib\\site-packages\\pyshark\\capture\\capture.py:177: UserWarning: The running eventloop has tasks but pyshark must set a new eventloop to continue. Existing tasks may not run.\n",
      "  warnings.warn(\"The running eventloop has tasks but pyshark must set a new eventloop to continue. \"\n"
     ]
    },
    {
     "ename": "RuntimeError",
     "evalue": "Cannot run the event loop while another loop is running",
     "output_type": "error",
     "traceback": [
      "\u001b[1;31m---------------------------------------------------------------------------\u001b[0m",
      "\u001b[1;31mRuntimeError\u001b[0m                              Traceback (most recent call last)",
      "Cell \u001b[1;32mIn[2], line 1\u001b[0m\n\u001b[1;32m----> 1\u001b[0m capture \u001b[38;5;241m=\u001b[39m \u001b[43mget_packets\u001b[49m\u001b[43m(\u001b[49m\u001b[43m)\u001b[49m\n",
      "File \u001b[1;32m~\\github_repos\\anomaly-detection-exercises\\pyshark_functions.py:5\u001b[0m, in \u001b[0;36mget_packets\u001b[1;34m()\u001b[0m\n\u001b[0;32m      3\u001b[0m \u001b[38;5;28;01mdef\u001b[39;00m \u001b[38;5;21mget_packets\u001b[39m():\n\u001b[0;32m      4\u001b[0m     capture \u001b[38;5;241m=\u001b[39m pyshark\u001b[38;5;241m.\u001b[39mLiveCapture()\n\u001b[1;32m----> 5\u001b[0m     \u001b[43mcapture\u001b[49m\u001b[38;5;241;43m.\u001b[39;49m\u001b[43msniff\u001b[49m\u001b[43m(\u001b[49m\u001b[43mtimeout\u001b[49m\u001b[38;5;241;43m=\u001b[39;49m\u001b[38;5;241;43m5\u001b[39;49m\u001b[43m)\u001b[49m\n\u001b[0;32m      6\u001b[0m     \u001b[38;5;28;01mreturn\u001b[39;00m capture\n",
      "File \u001b[1;32mC:\\ProgramData\\anaconda3\\lib\\site-packages\\pyshark\\capture\\capture.py:144\u001b[0m, in \u001b[0;36mCapture.load_packets\u001b[1;34m(self, packet_count, timeout)\u001b[0m\n\u001b[0;32m    141\u001b[0m         \u001b[38;5;28;01mraise\u001b[39;00m StopCapture()\n\u001b[0;32m    143\u001b[0m \u001b[38;5;28;01mtry\u001b[39;00m:\n\u001b[1;32m--> 144\u001b[0m     \u001b[38;5;28;43mself\u001b[39;49m\u001b[38;5;241;43m.\u001b[39;49m\u001b[43mapply_on_packets\u001b[49m\u001b[43m(\u001b[49m\n\u001b[0;32m    145\u001b[0m \u001b[43m        \u001b[49m\u001b[43mkeep_packet\u001b[49m\u001b[43m,\u001b[49m\u001b[43m \u001b[49m\u001b[43mtimeout\u001b[49m\u001b[38;5;241;43m=\u001b[39;49m\u001b[43mtimeout\u001b[49m\u001b[43m,\u001b[49m\u001b[43m \u001b[49m\u001b[43mpacket_count\u001b[49m\u001b[38;5;241;43m=\u001b[39;49m\u001b[43mpacket_count\u001b[49m\u001b[43m)\u001b[49m\n\u001b[0;32m    146\u001b[0m     \u001b[38;5;28mself\u001b[39m\u001b[38;5;241m.\u001b[39mloaded \u001b[38;5;241m=\u001b[39m \u001b[38;5;28;01mTrue\u001b[39;00m\n\u001b[0;32m    147\u001b[0m \u001b[38;5;28;01mexcept\u001b[39;00m asyncTimeoutError:\n",
      "File \u001b[1;32mC:\\ProgramData\\anaconda3\\lib\\site-packages\\pyshark\\capture\\capture.py:256\u001b[0m, in \u001b[0;36mCapture.apply_on_packets\u001b[1;34m(self, callback, timeout, packet_count)\u001b[0m\n\u001b[0;32m    254\u001b[0m \u001b[38;5;28;01mif\u001b[39;00m timeout \u001b[38;5;129;01mis\u001b[39;00m \u001b[38;5;129;01mnot\u001b[39;00m \u001b[38;5;28;01mNone\u001b[39;00m:\n\u001b[0;32m    255\u001b[0m     coro \u001b[38;5;241m=\u001b[39m asyncio\u001b[38;5;241m.\u001b[39mwait_for(coro, timeout)\n\u001b[1;32m--> 256\u001b[0m \u001b[38;5;28;01mreturn\u001b[39;00m \u001b[38;5;28;43mself\u001b[39;49m\u001b[38;5;241;43m.\u001b[39;49m\u001b[43meventloop\u001b[49m\u001b[38;5;241;43m.\u001b[39;49m\u001b[43mrun_until_complete\u001b[49m\u001b[43m(\u001b[49m\u001b[43mcoro\u001b[49m\u001b[43m)\u001b[49m\n",
      "File \u001b[1;32mC:\\ProgramData\\anaconda3\\lib\\asyncio\\base_events.py:625\u001b[0m, in \u001b[0;36mBaseEventLoop.run_until_complete\u001b[1;34m(self, future)\u001b[0m\n\u001b[0;32m    614\u001b[0m \u001b[38;5;250m\u001b[39m\u001b[38;5;124;03m\"\"\"Run until the Future is done.\u001b[39;00m\n\u001b[0;32m    615\u001b[0m \n\u001b[0;32m    616\u001b[0m \u001b[38;5;124;03mIf the argument is a coroutine, it is wrapped in a Task.\u001b[39;00m\n\u001b[1;32m   (...)\u001b[0m\n\u001b[0;32m    622\u001b[0m \u001b[38;5;124;03mReturn the Future's result, or raise its exception.\u001b[39;00m\n\u001b[0;32m    623\u001b[0m \u001b[38;5;124;03m\"\"\"\u001b[39;00m\n\u001b[0;32m    624\u001b[0m \u001b[38;5;28mself\u001b[39m\u001b[38;5;241m.\u001b[39m_check_closed()\n\u001b[1;32m--> 625\u001b[0m \u001b[38;5;28;43mself\u001b[39;49m\u001b[38;5;241;43m.\u001b[39;49m\u001b[43m_check_running\u001b[49m\u001b[43m(\u001b[49m\u001b[43m)\u001b[49m\n\u001b[0;32m    627\u001b[0m new_task \u001b[38;5;241m=\u001b[39m \u001b[38;5;129;01mnot\u001b[39;00m futures\u001b[38;5;241m.\u001b[39misfuture(future)\n\u001b[0;32m    628\u001b[0m future \u001b[38;5;241m=\u001b[39m tasks\u001b[38;5;241m.\u001b[39mensure_future(future, loop\u001b[38;5;241m=\u001b[39m\u001b[38;5;28mself\u001b[39m)\n",
      "File \u001b[1;32mC:\\ProgramData\\anaconda3\\lib\\asyncio\\base_events.py:586\u001b[0m, in \u001b[0;36mBaseEventLoop._check_running\u001b[1;34m(self)\u001b[0m\n\u001b[0;32m    584\u001b[0m     \u001b[38;5;28;01mraise\u001b[39;00m \u001b[38;5;167;01mRuntimeError\u001b[39;00m(\u001b[38;5;124m'\u001b[39m\u001b[38;5;124mThis event loop is already running\u001b[39m\u001b[38;5;124m'\u001b[39m)\n\u001b[0;32m    585\u001b[0m \u001b[38;5;28;01mif\u001b[39;00m events\u001b[38;5;241m.\u001b[39m_get_running_loop() \u001b[38;5;129;01mis\u001b[39;00m \u001b[38;5;129;01mnot\u001b[39;00m \u001b[38;5;28;01mNone\u001b[39;00m:\n\u001b[1;32m--> 586\u001b[0m     \u001b[38;5;28;01mraise\u001b[39;00m \u001b[38;5;167;01mRuntimeError\u001b[39;00m(\n\u001b[0;32m    587\u001b[0m         \u001b[38;5;124m'\u001b[39m\u001b[38;5;124mCannot run the event loop while another loop is running\u001b[39m\u001b[38;5;124m'\u001b[39m)\n",
      "\u001b[1;31mRuntimeError\u001b[0m: Cannot run the event loop while another loop is running"
     ]
    }
   ],
   "source": [
    "capture = get_packets()"
   ]
  },
  {
   "cell_type": "code",
   "execution_count": null,
   "id": "ff9eef6b-2428-4c8b-bcc5-9594870a9349",
   "metadata": {},
   "outputs": [],
   "source": [
    "capture[3]"
   ]
  },
  {
   "cell_type": "code",
   "execution_count": null,
   "id": "1e0ee598-1d8a-455b-b94b-f0df00c83186",
   "metadata": {},
   "outputs": [],
   "source": []
  }
 ],
 "metadata": {
  "kernelspec": {
   "display_name": "Python 3 (ipykernel)",
   "language": "python",
   "name": "python3"
  },
  "language_info": {
   "codemirror_mode": {
    "name": "ipython",
    "version": 3
   },
   "file_extension": ".py",
   "mimetype": "text/x-python",
   "name": "python",
   "nbconvert_exporter": "python",
   "pygments_lexer": "ipython3",
   "version": "3.10.9"
  }
 },
 "nbformat": 4,
 "nbformat_minor": 5
}
